Workbook
Name SegmentaciónDeDatos_País_de_Origen1: #N/A

Sheet Memoria
A1: REGISTRO DE ACCIONES
A2: SALA | I2: COCINA
A3: 1- Se ordenaron los datos por delimitación de comas | I3: 1- Se ordenaron los datos por delimitación de comas
A4: 2- Creada columna "Monto total", donde se recoge el precio total de la orden + propinas | I4: 2- Eliminada columna "Observaciones"
A5: 3- Reformateados los datos en columna "Propinas": Se sustituyó el punto decimal por una coma | I5: 3- Creada columna "Ganancia bruta": Precio de venta del plato * Cantidad
A6: 4- Reformateados los datos en las columnas "Hora de llegada" y "Hora de salida" a formato numérico excel | I6: 4- Creada columna "Ganancia neta: (Precio de venta- precio de coste) * Cantidad
A7: 5- Creadas columnas "Hora de llegada2" y "Hora de salida2", usado formato horario común | I7: 5- Creada columna "% de ganancia" donde se muestra el margen de beneficio respecto a la ganancia neta (neta/bruta *100)
A8: 6- Creada columna "Tiempo de permanencia" (Hsalida-Hllegada, sumados 15 min en caso de mesa ocupada) | I8: 6- Creada tabla dinámica (Agrupación por nº de orden y filtrado por el mismo)
A9: 7- Creada columna "Tiempo de preparación" (Suma total tiempo de preparación de los platos por orden)
A10: 8- Creada columna "Tiempo de degustación" (Permanencia - preparación, 0 si la suma es menor a 0)
A11: 9- Creada columna " Mesa Pagada" (Si tiempo de degustación<0, NO PAGADA)

Sheet Cocina
A1: Número de Orden | B1: Número de Mesa | C1: Nombre del Plato | D1: Descripción del Plato | E1: Costo Unitario | F1: Precio Unitario | G1: Cantidad Ordenada | H1: Tiempo de Preparación | I1: Ganancia bruta | J1: Ganancia neta | K1: Porcentaje ganancia
A2: 1 | B2: 10 | C2: Plato_2 | D2: Descripción del Plato_2 | E2: 18 | F2: 30 | G2: 3 | H2: 32 | I2: =spaces_3iWczBNnn5rbfoUlE0Jd_uploads_git_blob_d9e80ffbcef8a4adc6d29edd78618add5df6[[#This Row],[Precio Unitario]]*spaces_3iWczBNnn5rbfoUlE0Jd_uploads_git_blob_d9e80ffbcef8a4adc6d29edd78618add5df6[[#This Row],[Cantidad Ordenada]] -> 90 | J2: =(spaces_3iWczBNnn5rbfoUlE0Jd_uploads_git_blob_d9e80ffbcef8a4adc6d29edd78618add5df6[[#This Row],[Precio Unitario]]-spaces_3iWczBNnn5rbfoUlE0Jd_uploads_git_blob_d9e80ffbcef8a4adc6d29edd78618add5df6[[#This Row],[Costo Unitario]])*spaces_3iWczBNnn5rbfoUlE0Jd_uploads_git_blob_d9e80ffbcef8a4adc6d29edd78618add5df6[[#This Row],[Cantidad Ordenada]] -> 36 | K2: =(spaces_3iWczBNnn5rbfoUlE0Jd_uploads_git_blob_d9e80ffbcef8a4adc6d29edd78618add5df6[[#This Row],[Ganancia neta]]/spaces_3iWczBNnn5rbfoUlE0Jd_uploads_git_blob_d9e80ffbcef8a4adc6d29edd78618add5df6[[#This Row],[Ganancia bruta]]) -> 0.4
A3: 1 | B3: 10 | C3: Plato_7 | D3: Descripción del Plato_7 | E3: 14 | F3: 24 | G3: 2 | H3: 25 | I3: =spaces_3iWczBNnn5rbfoUlE0Jd_uploads_git_blob_d9e80ffbcef8a4adc6d29edd78618add5df6[[#This Row],[Precio Unitario]]*spaces_3iWczBNnn5rbfoUlE0Jd_uploads_git_blob_d9e80ffbcef8a4adc6d29edd78618add5df6[[#This Row],[Cantidad Ordenada]] -> 48 | J3: =(spaces_3iWczBNnn5rbfoUlE0Jd_uploads_git_blob_d9e80ffbcef8a4adc6d29edd78618add5df6[[#This Row],[Precio Unitario]]-spaces_3iWczBNnn5rbfoUlE0Jd_uploads_git_blob_d9e80ffbcef8a4adc6d29edd78618add5df6[[#This Row],[Costo Unitario]])*spaces_3iWczBNnn5rbfoUlE0Jd_uploads_git_blob_d9e80ffbcef8a4adc6d29edd78618add5df6[[#This Row],[Cantidad Ordenada]] -> 20 | K3: =(spaces_3iWczBNnn5rbfoUlE0Jd_uploads_git_blob_d9e80ffbcef8a4adc6d29edd78618add5df6[[#This Row],[Ganancia neta]]/spaces_3iWczBNnn5rbfoUlE0Jd_uploads_git_blob_d9e80ffbcef8a4adc6d29edd78618add5df6[[#This Row],[Ganancia bruta]]) -> 0.41666667
A4: 2 | B4: 6 | C4: Plato_17 | D4: Descripción del Plato_17 | E4: 19 | F4: 31 | G4: 1 | H4: 51 | I4: =spaces_3iWczBNnn5rbfoUlE0Jd_uploads_git_blob_d9e80ffbcef8a4adc6d29edd78618add5df6[[#This Row],[Precio Unitario]]*spaces_3iWczBNnn5rbfoUlE0Jd_uploads_git_blob_d9e80ffbcef8a4adc6d29edd78618add5df6[[#This Row],[Cantidad Ordenada]] -> 31 | J4: =(spaces_3iWczBNnn5rbfoUlE0Jd_uploads_git_blob_d9e80ffbcef8a4adc6d29edd78618add5df6[[#This Row],[Precio Unitario]]-spaces_3iWczBNnn5rbfoUlE0Jd_uploads_git_blob_d9e80ffbcef8a4adc6d29edd78618add5df6[[#This Row],[Costo Unitario]])*spaces_3iWczBNnn5rbfoUlE0Jd_uploads_git_blob_d9e80ffbcef8a4adc6d29edd78618add5df6[[#This Row],[Cantidad Ordenada]] -> 12 | K4: =(spaces_3iWczBNnn5rbfoUlE0Jd_uploads_git_blob_d9e80ffbcef8a4adc6d29edd78618add5df6[[#This Row],[Ganancia neta]]/spaces_3iWczBNnn5rbfoUlE0Jd_uploads_git_blob_d9e80ffbcef8a4adc6d29edd78618add5df6[[#This Row],[Ganancia bruta]]) -> 0.38709677
A5: 2 | B5: 6 | C5: Plato_6 | D5: Descripción del Plato_6 | E5: 16 | F5: 27 | G5: 1 | H5: 34 | I5: =spaces_3iWczBNnn5rbfoUlE0Jd_uploads_git_blob_d9e80ffbcef8a4adc6d29edd78618add5df6[[#This Row],[Precio Unitario]]*spaces_3iWczBNnn5rbfoUlE0Jd_uploads_git_blob_d9e80ffbcef8a4adc6d29edd78618add5df6[[#This Row],[Cantidad Ordenada]] -> 27 | J5: =(spaces_3iWczBNnn5rbfoUlE0Jd_uploads_git_blob_d9e80ffbcef8a4adc6d29edd78618add5df6[[#This Row],[Precio Unitario]]-spaces_3iWczBNnn5rbfoUlE0Jd_uploads_git_blob_d9e80ffbcef8a4adc6d29edd78618add5df6[[#This Row],[Costo Unitario]])*spaces_3iWczBNnn5rbfoUlE0Jd_uploads_git_blob_d9e80ffbcef8a4adc6d29edd78618add5df6[[#This Row],[Cantidad Ordenada]] -> 11 | K5: =(spaces_3iWczBNnn5rbfoUlE0Jd_uploads_git_blob_d9e80ffbcef8a4adc6d29edd78618add5df6[[#This Row],[Ganancia neta]]/spaces_3iWczBNnn5rbfoUlE0Jd_uploads_git_blob_d9e80ffbcef8a4adc6d29edd78618add5df6[[#This Row],[Ganancia bruta]]) -> 0.40740741
A6: 3 | B6: 20 | C6: Plato_17 | D6: Descripción del Plato_17 | E6: 19 | F6: 31 | G6: 1 | H6: 27 | I6: =spaces_3iWczBNnn5rbfoUlE0Jd_uploads_git_blob_d9e80ffbcef8a4adc6d29edd78618add5df6[[#This Row],[Precio Unitario]]*spaces_3iWczBNnn5rbfoUlE0Jd_uploads_git_blob_d9e80ffbcef8a4adc6d29edd78618add5df6[[#This Row],[Cantidad Ordenada]] -> 31 | J6: =(spaces_3iWczBNnn5rbfoUlE0Jd_uploads_git_blob_d9e80ffbcef8a4adc6d29edd78618add5df6[[#This Row],[Precio Unitario]]-spaces_3iWczBNnn5rbfoUlE0Jd_uploads_git_blob_d9e80ffbcef8a4adc6d29edd78618add5df6[[#This Row],[Costo Unitario]])*spaces_3iWczBNnn5rbfoUlE0Jd_uploads_git_blob_d9e80ffbcef8a4adc6d29edd78618add5df6[[#This Row],[Cantidad Ordenada]] -> 12 | K6: =(spaces_3iWczBNnn5rbfoUlE0Jd_uploads_git_blob_d9e80ffbcef8a4adc6d29edd78618add5df6[[#This Row],[Ganancia neta]]/spaces_3iWczBNnn5rbfoUlE0Jd_uploads_git_blob_d9e80ffbcef8a4adc6d29edd78618add5df6[[#This Row],[Ganancia bruta]]) -> 0.38709677
A7: 3 | B7: 20 | C7: Plato_19 | D7: Descripción del Plato_19 | E7: 22 | F7: 36 | G7: 1 | H7: 36 | I7: =spaces_3iWczBNnn5rbfoUlE0Jd_uploads_git_blob_d9e80ffbcef8a4adc6d29edd78618add5df6[[#This Row],[Precio Unitario]]*spaces_3iWczBNnn5rbfoUlE0Jd_uploads_git_blob_d9e80ffbcef8a4adc6d29edd78618add5df6[[#This Row],[Cantidad Ordenada]] -> 36 | J7: =(spaces_3iWczBNnn5rbfoUlE0Jd_uploads_git_blob_d9e80ffbcef8a4adc6d29edd78618add5df6[[#This Row],[Precio Unitario]]-spaces_3iWczBNnn5rbfoUlE0Jd_uploads_git_blob_d9e80ffbcef8a4adc6d29edd78618add5df6[[#This Row],[Costo Unitario]])*spaces_3iWczBNnn5rbfoUlE0Jd_uploads_git_blob_d9e80ffbcef8a4adc6d29edd78618add5df6[[#This Row],[Cantidad Ordenada]] -> 14 | K7: =(spaces_3iWczBNnn5rbfoUlE0Jd_uploads_git_blob_d9e80ffbcef8a4adc6d29edd78618add5df6[[#This Row],[Ganancia neta]]/spaces_3iWczBNnn5rbfoUlE0Jd_uploads_git_blob_d9e80ffbcef8a4adc6d29edd78618add5df6[[#This Row],[Ganancia bruta]]) -> 0.38888889
A8: 3 | B8: 20 | C8: Plato_20 | D8: Descripción del Plato_20 | E8: 25 | F8: 40 | G8: 1 | H8: 9 | I8: =spaces_3iWczBNnn5rbfoUlE0Jd_uploads_git_blob_d9e80ffbcef8a4adc6d29edd78618add5df6[[#This Row],[Precio Unitario]]*spaces_3iWczBNnn5rbfoUlE0Jd_uploads_git_blob_d9e80ffbcef8a4adc6d29edd78618add5df6[[#This Row],[Cantidad Ordenada]] -> 40 | J8: =(spaces_3iWczBNnn5rbfoUlE0Jd_uploads_git_blob_d9e80ffbcef8a4adc6d29edd78618add5df6[[#This Row],[Precio Unitario]]-spaces_3iWczBNnn5rbfoUlE0Jd_uploads_git_blob_d9e80ffbcef8a4adc6d29edd78618add5df6[[#This Row],[Costo Unitario]])*spaces_3iWczBNnn5rbfoUlE0Jd_uploads_git_blob_d9e80ffbcef8a4adc6d29edd78618add5df6[[#This Row],[Cantidad Ordenada]] -> 15 | K8: =(spaces_3iWczBNnn5rbfoUlE0Jd_uploads_git_blob_d9e80ffbcef8a4adc6d29edd78618add5df6[[#This Row],[Ganancia neta]]/spaces_3iWczBNnn5rbfoUlE0Jd_uploads_git_blob_d9e80ffbcef8a4adc6d29edd78618add5df6[[#This Row],[Ganancia bruta]]) -> 0.375
A9: 3 | B9: 20 | C9: Plato_9 | D9: Descripción del Plato_9 | E9: 17 | F9: 29 | G9: 2 | H9: 54 | I9: =spaces_3iWczBNnn5rbfoUlE0Jd_uploads_git_blob_d9e80ffbcef8a4adc6d29edd78618add5df6[[#This Row],[Precio Unitario]]*spaces_3iWczBNnn5rbfoUlE0Jd_uploads_git_blob_d9e80ffbcef8a4adc6d29edd78618add5df6[[#This Row],[Cantidad Ordenada]] -> 58 | J9: =(spaces_3iWczBNnn5rbfoUlE0Jd_uploads_git_blob_d9e80ffbcef8a4adc6d29edd78618add5df6[[#This Row],[Precio Unitario]]-spaces_3iWczBNnn5rbfoUlE0Jd_uploads_git_blob_d9e80ffbcef8a4adc6d29edd78618add5df6[[#This Row],[Costo Unitario]])*spaces_3iWczBNnn5rbfoUlE0Jd_uploads_git_blob_d9e80ffbcef8a4adc6d29edd78618add5df6[[#This Row],[Cantidad Ordenada]] -> 24 | K9: =(spaces_3iWczBNnn5rbfoUlE0Jd_uploads_git_blob_d9e80ffbcef8a4adc6d29edd78618add5df6[[#This Row],[Ganancia neta]]/spaces_3iWczBNnn5rbfoUlE0Jd_uploads_git_blob_d9e80ffbcef8a4adc6d29edd78618add5df6[[#This Row],[Ganancia bruta]]) -> 0.4137931
A10: 4 | B10: 3 | C10: Plato_11 | D10: Descripción del Plato_11 | E10: 20 | F10: 33 | G10: 3 | H10: 23 | I10: =spaces_3iWczBNnn5rbfoUlE0Jd_uploads_git_blob_d9e80ffbcef8a4adc6d29edd78618add5df6[[#This Row],[Precio Unitario]]*spaces_3iWczBNnn5rbfoUlE0Jd_uploads_git_blob_d9e80ffbcef8a4adc6d29edd78618add5df6[[#This Row],[Cantidad Ordenada]] -> 99 | J10: =(spaces_3iWczBNnn5rbfoUlE0Jd_uploads_git_blob_d9e80ffbcef8a4adc6d29edd78618add5df6[[#This Row],[Precio Unitario]]-spaces_3iWczBNnn5rbfoUlE0Jd_uploads_git_blob_d9e80ffbcef8a4adc6d29edd78618add5df6[[#This Row],[Costo Unitario]])*spaces_3iWczBNnn5rbfoUlE0Jd_uploads_git_blob_d9e80ffbcef8a4adc6d29edd78618add5df6[[#This Row],[Cantidad Ordenada]] -> 39 | K10: =(spaces_3iWczBNnn5rbfoUlE0Jd_uploads_git_blob_d9e80ffbcef8a4adc6d29edd78618add5df6[[#This Row],[Ganancia neta]]/spaces_3iWczBNnn5rbfoUlE0Jd_uploads_git_blob_d9e80ffbcef8a4adc6d29edd78618add5df6[[#This Row],[Ganancia bruta]]) -> 0.39393939
A11: 4 | B11: 3 | C11: Plato_16 | D11: Descripción del Plato_16 | E11: 16 | F11: 28 | G11: 3 | H11: 17 | I11: =spaces_3iWczBNnn5rbfoUlE0Jd_uploads_git_blob_d9e80ffbcef8a4adc6d29edd78618add5df6[[#This Row],[Precio Unitario]]*spaces_3iWczBNnn5rbfoUlE0Jd_uploads_git_blob_d9e80ffbcef8a4adc6d29edd78618add5df6[[#This Row],[Cantidad Ordenada]] -> 84 | J11: =(spaces_3iWczBNnn5rbfoUlE0Jd_uploads_git_blob_d9e80ffbcef8a4adc6d29edd78618add5df6[[#This Row],[Precio Unitario]]-spaces_3iWczBNnn5rbfoUlE0Jd_uploads_git_blob_d9e80ffbcef8a4adc6d29edd78618add5df6[[#This Row],[Costo Unitario]])*spaces_3iWczBNnn5rbfoUlE0Jd_uploads_git_blob_d9e80ffbcef8a4adc6d29edd78618add5df6[[#This Row],[Cantidad Ordenada]] -> 36 | K11: =(spaces_3iWczBNnn5rbfoUlE0Jd_uploads_git_blob_d9e80ffbcef8a4adc6d29edd78618add5df6[[#This Row],[Ganancia neta]]/spaces_3iWczBNnn5rbfoUlE0Jd_uploads_git_blob_d9e80ffbcef8a4adc6d29edd78618add5df6[[#This Row],[Ganancia bruta]]) -> 0.42857143
A12: 5 | B12: 8 | C12: Plato_12 | D12: Descripción del Plato_12 | E12: 11 | F12: 19 | G12: 1 | H12: 8 | I12: =spaces_3iWczBNnn5rbfoUlE0Jd_uploads_git_blob_d9e80ffbcef8a4adc6d29edd78618add5df6[[#This Row],[Precio Unitario]]*spaces_3iWczBNnn5rbfoUlE0Jd_uploads_git_blob_d9e80ffbcef8a4adc6d29edd78618add5df6[[#This Row],[Cantidad Ordenada]] -> 19 | J12: =(spaces_3iWczBNnn5rbfoUlE0Jd_uploads_git_blob_d9e80ffbcef8a4adc6d29edd78618add5df6[[#This Row],[Precio Unitario]]-spaces_3iWczBNnn5rbfoUlE0Jd_uploads_git_blob_d9e80ffbcef8a4adc6d29edd78618add5df6[[#This Row],[Costo Unitario]])*spaces_3iWczBNnn5rbfoUlE0Jd_uploads_git_blob_d9e80ffbcef8a4adc6d29edd78618add5df6[[#This Row],[Cantidad Ordenada]] -> 8 | K12: =(spaces_3iWczBNnn5rbfoUlE0Jd_uploads_git_blob_d9e80ffbcef8a4adc6d29edd78618add5df6[[#This Row],[Ganancia neta]]/spaces_3iWczBNnn5rbfoUlE0Jd_uploads_git_blob_d9e80ffbcef8a4adc6d29edd78618add5df6[[#This Row],[Ganancia bruta]]) -> 0.42105263
A13: 5 | B13: 8 | C13: Plato_7 | D13: Descripción del Plato_7 | E13: 14 | F13: 24 | G13: 2 | H13: 9 | I13: =spaces_3iWczBNnn5rbfoUlE0Jd_uploads_git_blob_d9e80ffbcef8a4adc6d29edd78618add5df6[[#This Row],[Precio Unitario]]*spaces_3iWczBNnn5rbfoUlE0Jd_uploads_git_blob_d9e80ffbcef8a4adc6d29edd78618add5df6[[#This Row],[Cantidad Ordenada]] -> 48 | J13: =(spaces_3iWczBNnn5rbfoUlE0Jd_uploads_git_blob_d9e80ffbcef8a4adc6d29edd78618add5df6[[#This Row],[Precio Unitario]]-spaces_3iWczBNnn5rbfoUlE0Jd_uploads_git_blob_d9e80ffbcef8a4adc6d29edd78618add5df6[[#This Row],[Costo Unitario]])*spaces_3iWczBNnn5rbfoUlE0Jd_uploads_git_blob_d9e80ffbcef8a4adc6d29edd78618add5df6[[#This Row],[Cantidad Ordenada]] -> 20 | K13: =(spaces_3iWczBNnn5rbfoUlE0Jd_uploads_git_blob_d9e80ffbcef8a4adc6d29edd78618add5df6[[#This Row],[Ganancia neta]]/spaces_3iWczBNnn5rbfoUlE0Jd_uploads_git_blob_d9e80ffbcef8a4adc6d29edd78618add5df6[[#This Row],[Ganancia bruta]]) -> 0.41666667
... A1903: 767 | B1903: 10 | C1903: Plato_9 | D1903: Descripción del Plato_9 | E1903: 17 | F1903: 29 | G1903: 2 | H1903: 12 | I1903: =spaces_3iWczBNnn5rbfoUlE0Jd_uploads_git_blob_d9e80ffbcef8a4adc6d29edd78618add5df6[[#This Row],[Precio Unitario]]*spaces_3iWczBNnn5rbfoUlE0Jd_uploads_git_blob_d9e80ffbcef8a4adc6d29edd78618add5df6[[#This Row],[Cantidad Ordenada]] -> 58 | J1903: =(spaces_3iWczBNnn5rbfoUlE0Jd_uploads_git_blob_d9e80ffbcef8a4adc6d29edd78618add5df6[[#This Row],[Precio Unitario]]-spaces_3iWczBNnn5rbfoUlE0Jd_uploads_git_blob_d9e80ffbcef8a4adc6d29edd78618add5df6[[#This Row],[Costo Unitario]])*spaces_3iWczBNnn5rbfoUlE0Jd_uploads_git_blob_d9e80ffbcef8a4adc6d29edd78618add5df6[[#This Row],[Cantidad Ordenada]] -> 24 | K1903: =(spaces_3iWczBNnn5rbfoUlE0Jd_uploads_git_blob_d9e80ffbcef8a4adc6d29edd78618add5df6[[#This Row],[Ganancia neta]]/spaces_3iWczBNnn5rbfoUlE0Jd_uploads_git_blob_d9e80ffbcef8a4adc6d29edd78618add5df6[[#This Row],[Ganancia bruta]]) -> 0.4137931

Sheet Sala
A1: Número de Mesa | B1: Nombre del Cliente | C1: Número de Comensales | D1: Hora de Llegada | E1: Hora de Salida | F1: Mesero Asignado | G1: Tipo de Servicio | H1: Método de Pago | I1: Propina | J1: Estado de la Mesa | K1: Número de Orden | L1: País de Origen | M1: Platos Ordenados | N1: Monto total | O1: Fecha de factura | P1: Hora de llegada2 | Q1: Hora de salida2 | R1: Tiempo de permanencia | S1: Tiempo de preparación total | T1: Tiempo degustación | U1: Mesa pagada
A2: 10 | B2: Cliente_724 | C2: 6 | D2: 45017.047 | E2: 45017.16 | F2: Mesero_3 | G2: Almuerzo | H2: Tarjeta de débito | I2: 48.55 | J2: Reservada | K2: 1 | L2: España | M2: Plato_7, Plato_2 | N2: =_xlfn.XLOOKUP(spaces_3iWczBNnn5rbfoUlE0Jd_uploads_git_blob_9864c7f811c613c3faab876659c6423__25[[#This Row],[Número de Orden]],Cocinadinamica!B3:B771,Cocinadinamica!C3:C771) -> 56 | O2: =spaces_3iWczBNnn5rbfoUlE0Jd_uploads_git_blob_9864c7f811c613c3faab876659c6423__25[[#This Row],[Hora de Llegada]] -> 45017.047 | P2: =spaces_3iWczBNnn5rbfoUlE0Jd_uploads_git_blob_9864c7f811c613c3faab876659c6423__25[[#This Row],[Hora de Llegada]] -> 45017.047 | Q2: =spaces_3iWczBNnn5rbfoUlE0Jd_uploads_git_blob_9864c7f811c613c3faab876659c6423__25[[#This Row],[Hora de Salida]] -> 45017.16 | R2: {=_xlfn.IFS(spaces_3iWczBNnn5rbfoUlE0Jd_uploads_git_blob_9864c7f811c613c3faab876659c6423__25[[#This Row],[Estado de la Mesa]]="Ocupada",(15/1440)+spaces_3iWczBNnn5rbfoUlE0Jd_uploads_git_blob_9864c7f811c613c3faab876659c6423__25[[#This Row],[Hora de salida2]]-spaces_3iWczBNnn5rbfoUlE0Jd_uploads_git_blob_9864c7f811c613c3faab876659c6423__25[[#This Row],[Hora de llegada2]],spaces_3iWczBNnn5rbfoUlE0Jd_uploads_git_blob_9864c7f811c613c3faab876659c6423__25[[#This Row],[Estado de la Mesa]]<>"Ocupada",spaces_3iWczBNnn5rbfoUlE0Jd_uploads_git_blob_9864c7f811c613c3faab876659c6423__25[[#This Row],[Hora de salida2]]-spaces_3iWczBNnn5rbfoUlE0Jd_uploads_git_blob_9864c7f811c613c3faab876659c6423__25[[#This Row],[Hora de llegada2]])} -> 0.11319444 | S2: =_xlfn.XLOOKUP(spaces_3iWczBNnn5rbfoUlE0Jd_uploads_git_blob_9864c7f811c613c3faab876659c6423__25[[#This Row],[Número de Orden]],Cocinadinamica!E3:E771,Cocinadinamica!F3:F771)/1440 -> 0.039583333 | T2: {=_xlfn.IFS((spaces_3iWczBNnn5rbfoUlE0Jd_uploads_git_blob_9864c7f811c613c3faab876659c6423__25[[#This Row],[Tiempo de permanencia]]-spaces_3iWczBNnn5rbfoUlE0Jd_uploads_git_blob_9864c7f811c613c3faab876659c6423__25[[#This Row],[Tiempo de preparación total]])>0,spaces_3iWczBNnn5rbfoUlE0Jd_uploads_git_blob_9864c7f811c613c3faab876659c6423__25[[#This Row],[Tiempo de permanencia]]-spaces_3iWczBNnn5rbfoUlE0Jd_uploads_git_blob_9864c7f811c613c3faab876659c6423__25[[#This Row],[Tiempo de preparación total]],spaces_3iWczBNnn5rbfoUlE0Jd_uploads_git_blob_9864c7f811c613c3faab876659c6423__25[[#This Row],[Tiempo de permanencia]]-spaces_3iWczBNnn5rbfoUlE0Jd_uploads_git_blob_9864c7f811c613c3faab876659c6423__25[[#This Row],[Tiempo de preparación total]]<0,0)} -> 0.073611111 | U2: {=_xlfn.IFS(spaces_3iWczBNnn5rbfoUlE0Jd_uploads_git_blob_9864c7f811c613c3faab876659c6423__25[[#This Row],[Tiempo degustación]]=0,"NO PAGADA",spaces_3iWczBNnn5rbfoUlE0Jd_uploads_git_blob_9864c7f811c613c3faab876659c6423__25[[#This Row],[Tiempo degustación]]>0, "PAGADA")} -> PAGADA
A3: 6 | B3: Cliente_538 | C3: 6 | D3: 45017.061 | E3: 45017.159 | F3: Mesero_1 | G3: Desayuno | H3: Efectivo | I3: 43.3 | J3: Reservada | K3: 2 | L3: Colombia | M3: Plato_17, Plato_6 | N3: =_xlfn.XLOOKUP(spaces_3iWczBNnn5rbfoUlE0Jd_uploads_git_blob_9864c7f811c613c3faab876659c6423__25[[#This Row],[Número de Orden]],Cocinadinamica!B4:B772,Cocinadinamica!C4:C772) -> 23 | O3: =spaces_3iWczBNnn5rbfoUlE0Jd_uploads_git_blob_9864c7f811c613c3faab876659c6423__25[[#This Row],[Hora de Llegada]] -> 45017.061 | P3: =spaces_3iWczBNnn5rbfoUlE0Jd_uploads_git_blob_9864c7f811c613c3faab876659c6423__25[[#This Row],[Hora de Llegada]] -> 45017.061 | Q3: =spaces_3iWczBNnn5rbfoUlE0Jd_uploads_git_blob_9864c7f811c613c3faab876659c6423__25[[#This Row],[Hora de Salida]] -> 45017.159 | R3: {=_xlfn.IFS(spaces_3iWczBNnn5rbfoUlE0Jd_uploads_git_blob_9864c7f811c613c3faab876659c6423__25[[#This Row],[Estado de la Mesa]]="Ocupada",(15/1440)+spaces_3iWczBNnn5rbfoUlE0Jd_uploads_git_blob_9864c7f811c613c3faab876659c6423__25[[#This Row],[Hora de salida2]]-spaces_3iWczBNnn5rbfoUlE0Jd_uploads_git_blob_9864c7f811c613c3faab876659c6423__25[[#This Row],[Hora de llegada2]],spaces_3iWczBNnn5rbfoUlE0Jd_uploads_git_blob_9864c7f811c613c3faab876659c6423__25[[#This Row],[Estado de la Mesa]]<>"Ocupada",spaces_3iWczBNnn5rbfoUlE0Jd_uploads_git_blob_9864c7f811c613c3faab876659c6423__25[[#This Row],[Hora de salida2]]-spaces_3iWczBNnn5rbfoUlE0Jd_uploads_git_blob_9864c7f811c613c3faab876659c6423__25[[#This Row],[Hora de llegada2]])} -> 0.097916667 | S3: =_xlfn.XLOOKUP(spaces_3iWczBNnn5rbfoUlE0Jd_uploads_git_blob_9864c7f811c613c3faab876659c6423__25[[#This Row],[Número de Orden]],Cocinadinamica!E4:E772,Cocinadinamica!F4:F772)/1440 -> 0.059027778 | T3: {=_xlfn.IFS((spaces_3iWczBNnn5rbfoUlE0Jd_uploads_git_blob_9864c7f811c613c3faab876659c6423__25[[#This Row],[Tiempo de permanencia]]-spaces_3iWczBNnn5rbfoUlE0Jd_uploads_git_blob_9864c7f811c613c3faab876659c6423__25[[#This Row],[Tiempo de preparación total]])>0,spaces_3iWczBNnn5rbfoUlE0Jd_uploads_git_blob_9864c7f811c613c3faab876659c6423__25[[#This Row],[Tiempo de permanencia]]-spaces_3iWczBNnn5rbfoUlE0Jd_uploads_git_blob_9864c7f811c613c3faab876659c6423__25[[#This Row],[Tiempo de preparación total]],spaces_3iWczBNnn5rbfoUlE0Jd_uploads_git_blob_9864c7f811c613c3faab876659c6423__25[[#This Row],[Tiempo de permanencia]]-spaces_3iWczBNnn5rbfoUlE0Jd_uploads_git_blob_9864c7f811c613c3faab876659c6423__25[[#This Row],[Tiempo de preparación total]]<0,0)} -> 0.038888889 | U3: {=_xlfn.IFS(spaces_3iWczBNnn5rbfoUlE0Jd_uploads_git_blob_9864c7f811c613c3faab876659c6423__25[[#This Row],[Tiempo degustación]]=0,"NO PAGADA",spaces_3iWczBNnn5rbfoUlE0Jd_uploads_git_blob_9864c7f811c613c3faab876659c6423__25[[#This Row],[Tiempo degustación]]>0, "PAGADA")} -> PAGADA
A4: 20 | B4: Cliente_911 | C4: 1 | D4: 45017.02 | E4: 45017.164 | F4: Mesero_2 | G4: Desayuno | H4: Tarjeta de crédito | I4: 30.87 | J4: Libre | K4: 3 | L4: Brasil | M4: Plato_20, Plato_17, Plato_19, Plato_9 | N4: =_xlfn.XLOOKUP(spaces_3iWczBNnn5rbfoUlE0Jd_uploads_git_blob_9864c7f811c613c3faab876659c6423__25[[#This Row],[Número de Orden]],Cocinadinamica!B5:B773,Cocinadinamica!C5:C773) -> 65 | O4: =spaces_3iWczBNnn5rbfoUlE0Jd_uploads_git_blob_9864c7f811c613c3faab876659c6423__25[[#This Row],[Hora de Llegada]] -> 45017.02 | P4: =spaces_3iWczBNnn5rbfoUlE0Jd_uploads_git_blob_9864c7f811c613c3faab876659c6423__25[[#This Row],[Hora de Llegada]] -> 45017.02 | Q4: =spaces_3iWczBNnn5rbfoUlE0Jd_uploads_git_blob_9864c7f811c613c3faab876659c6423__25[[#This Row],[Hora de Salida]] -> 45017.164 | R4: {=_xlfn.IFS(spaces_3iWczBNnn5rbfoUlE0Jd_uploads_git_blob_9864c7f811c613c3faab876659c6423__25[[#This Row],[Estado de la Mesa]]="Ocupada",(15/1440)+spaces_3iWczBNnn5rbfoUlE0Jd_uploads_git_blob_9864c7f811c613c3faab876659c6423__25[[#This Row],[Hora de salida2]]-spaces_3iWczBNnn5rbfoUlE0Jd_uploads_git_blob_9864c7f811c613c3faab876659c6423__25[[#This Row],[Hora de llegada2]],spaces_3iWczBNnn5rbfoUlE0Jd_uploads_git_blob_9864c7f811c613c3faab876659c6423__25[[#This Row],[Estado de la Mesa]]<>"Ocupada",spaces_3iWczBNnn5rbfoUlE0Jd_uploads_git_blob_9864c7f811c613c3faab876659c6423__25[[#This Row],[Hora de salida2]]-spaces_3iWczBNnn5rbfoUlE0Jd_uploads_git_blob_9864c7f811c613c3faab876659c6423__25[[#This Row],[Hora de llegada2]])} -> 0.14375 | S4: =_xlfn.XLOOKUP(spaces_3iWczBNnn5rbfoUlE0Jd_uploads_git_blob_9864c7f811c613c3faab876659c6423__25[[#This Row],[Número de Orden]],Cocinadinamica!E5:E773,Cocinadinamica!F5:F773)/1440 -> 0.0875 | T4: {=_xlfn.IFS((spaces_3iWczBNnn5rbfoUlE0Jd_uploads_git_blob_9864c7f811c613c3faab876659c6423__25[[#This Row],[Tiempo de permanencia]]-spaces_3iWczBNnn5rbfoUlE0Jd_uploads_git_blob_9864c7f811c613c3faab876659c6423__25[[#This Row],[Tiempo de preparación total]])>0,spaces_3iWczBNnn5rbfoUlE0Jd_uploads_git_blob_9864c7f811c613c3faab876659c6423__25[[#This Row],[Tiempo de permanencia]]-spaces_3iWczBNnn5rbfoUlE0Jd_uploads_git_blob_9864c7f811c613c3faab876659c6423__25[[#This Row],[Tiempo de preparación total]],spaces_3iWczBNnn5rbfoUlE0Jd_uploads_git_blob_9864c7f811c613c3faab876659c6423__25[[#This Row],[Tiempo de permanencia]]-spaces_3iWczBNnn5rbfoUlE0Jd_uploads_git_blob_9864c7f811c613c3faab876659c6423__25[[#This Row],[Tiempo de preparación total]]<0,0)} -> 0.05625 | U4: {=_xlfn.IFS(spaces_3iWczBNnn5rbfoUlE0Jd_uploads_git_blob_9864c7f811c613c3faab876659c6423__25[[#This Row],[Tiempo degustación]]=0,"NO PAGADA",spaces_3iWczBNnn5rbfoUlE0Jd_uploads_git_blob_9864c7f811c613c3faab876659c6423__25[[#This Row],[Tiempo degustación]]>0, "PAGADA")} -> PAGADA
A5: 3 | B5: Cliente_129 | C5: 1 | D5: 45017.127 | E5: 45017.188 | F5: Mesero_5 | G5: Almuerzo | H5: Tarjeta de crédito | I5: 34.68 | J5: Libre | K5: 4 | L5: Paraguay | M5: Plato_11, Plato_16 | N5: =_xlfn.XLOOKUP(spaces_3iWczBNnn5rbfoUlE0Jd_uploads_git_blob_9864c7f811c613c3faab876659c6423__25[[#This Row],[Número de Orden]],Cocinadinamica!B6:B774,Cocinadinamica!C6:C774) -> 75 | O5: =spaces_3iWczBNnn5rbfoUlE0Jd_uploads_git_blob_9864c7f811c613c3faab876659c6423__25[[#This Row],[Hora de Llegada]] -> 45017.127 | P5: =spaces_3iWczBNnn5rbfoUlE0Jd_uploads_git_blob_9864c7f811c613c3faab876659c6423__25[[#This Row],[Hora de Llegada]] -> 45017.127 | Q5: =spaces_3iWczBNnn5rbfoUlE0Jd_uploads_git_blob_9864c7f811c613c3faab876659c6423__25[[#This Row],[Hora de Salida]] -> 45017.188 | R5: {=_xlfn.IFS(spaces_3iWczBNnn5rbfoUlE0Jd_uploads_git_blob_9864c7f811c613c3faab876659c6423__25[[#This Row],[Estado de la Mesa]]="Ocupada",(15/1440)+spaces_3iWczBNnn5rbfoUlE0Jd_uploads_git_blob_9864c7f811c613c3faab876659c6423__25[[#This Row],[Hora de salida2]]-spaces_3iWczBNnn5rbfoUlE0Jd_uploads_git_blob_9864c7f811c613c3faab876659c6423__25[[#This Row],[Hora de llegada2]],spaces_3iWczBNnn5rbfoUlE0Jd_uploads_git_blob_9864c7f811c613c3faab876659c6423__25[[#This Row],[Estado de la Mesa]]<>"Ocupada",spaces_3iWczBNnn5rbfoUlE0Jd_uploads_git_blob_9864c7f811c613c3faab876659c6423__25[[#This Row],[Hora de salida2]]-spaces_3iWczBNnn5rbfoUlE0Jd_uploads_git_blob_9864c7f811c613c3faab876659c6423__25[[#This Row],[Hora de llegada2]])} -> 0.061111111 | S5: =_xlfn.XLOOKUP(spaces_3iWczBNnn5rbfoUlE0Jd_uploads_git_blob_9864c7f811c613c3faab876659c6423__25[[#This Row],[Número de Orden]],Cocinadinamica!E6:E774,Cocinadinamica!F6:F774)/1440 -> 0.027777778 | T5: {=_xlfn.IFS((spaces_3iWczBNnn5rbfoUlE0Jd_uploads_git_blob_9864c7f811c613c3faab876659c6423__25[[#This Row],[Tiempo de permanencia]]-spaces_3iWczBNnn5rbfoUlE0Jd_uploads_git_blob_9864c7f811c613c3faab876659c6423__25[[#This Row],[Tiempo de preparación total]])>0,spaces_3iWczBNnn5rbfoUlE0Jd_uploads_git_blob_9864c7f811c613c3faab876659c6423__25[[#This Row],[Tiempo de permanencia]]-spaces_3iWczBNnn5rbfoUlE0Jd_uploads_git_blob_9864c7f811c613c3faab876659c6423__25[[#This Row],[Tiempo de preparación total]],spaces_3iWczBNnn5rbfoUlE0Jd_uploads_git_blob_9864c7f811c613c3faab876659c6423__25[[#This Row],[Tiempo de permanencia]]-spaces_3iWczBNnn5rbfoUlE0Jd_uploads_git_blob_9864c7f811c613c3faab876659c6423__25[[#This Row],[Tiempo de preparación total]]<0,0)} -> 0.033333333 | U5: {=_xlfn.IFS(spaces_3iWczBNnn5rbfoUlE0Jd_uploads_git_blob_9864c7f811c613c3faab876659c6423__25[[#This Row],[Tiempo degustación]]=0,"NO PAGADA",spaces_3iWczBNnn5rbfoUlE0Jd_uploads_git_blob_9864c7f811c613c3faab876659c6423__25[[#This Row],[Tiempo degustación]]>0, "PAGADA")} -> PAGADA
A6: 8 | B6: Cliente_938 | C6: 2 | D6: 45017.001 | E6: 45017.088 | F6: Mesero_4 | G6: Almuerzo | H6: Tarjeta de crédito | I6: 24.33 | J6: Libre | K6: 5 | L6: Perú | M6: Plato_12, Plato_7 | N6: =_xlfn.XLOOKUP(spaces_3iWczBNnn5rbfoUlE0Jd_uploads_git_blob_9864c7f811c613c3faab876659c6423__25[[#This Row],[Número de Orden]],Cocinadinamica!B7:B775,Cocinadinamica!C7:C775) -> 28 | O6: =spaces_3iWczBNnn5rbfoUlE0Jd_uploads_git_blob_9864c7f811c613c3faab876659c6423__25[[#This Row],[Hora de Llegada]] -> 45017.001 | P6: =spaces_3iWczBNnn5rbfoUlE0Jd_uploads_git_blob_9864c7f811c613c3faab876659c6423__25[[#This Row],[Hora de Llegada]] -> 45017.001 | Q6: =spaces_3iWczBNnn5rbfoUlE0Jd_uploads_git_blob_9864c7f811c613c3faab876659c6423__25[[#This Row],[Hora de Salida]] -> 45017.088 | R6: {=_xlfn.IFS(spaces_3iWczBNnn5rbfoUlE0Jd_uploads_git_blob_9864c7f811c613c3faab876659c6423__25[[#This Row],[Estado de la Mesa]]="Ocupada",(15/1440)+spaces_3iWczBNnn5rbfoUlE0Jd_uploads_git_blob_9864c7f811c613c3faab876659c6423__25[[#This Row],[Hora de salida2]]-spaces_3iWczBNnn5rbfoUlE0Jd_uploads_git_blob_9864c7f811c613c3faab876659c6423__25[[#This Row],[Hora de llegada2]],spaces_3iWczBNnn5rbfoUlE0Jd_uploads_git_blob_9864c7f811c613c3faab876659c6423__25[[#This Row],[Estado de la Mesa]]<>"Ocupada",spaces_3iWczBNnn5rbfoUlE0Jd_uploads_git_blob_9864c7f811c613c3faab876659c6423__25[[#This Row],[Hora de salida2]]-spaces_3iWczBNnn5rbfoUlE0Jd_uploads_git_blob_9864c7f811c613c3faab876659c6423__25[[#This Row],[Hora de llegada2]])} -> 0.086805556 | S6: =_xlfn.XLOOKUP(spaces_3iWczBNnn5rbfoUlE0Jd_uploads_git_blob_9864c7f811c613c3faab876659c6423__25[[#This Row],[Número de Orden]],Cocinadinamica!E7:E775,Cocinadinamica!F7:F775)/1440 -> 0.011805556 | T6: {=_xlfn.IFS((spaces_3iWczBNnn5rbfoUlE0Jd_uploads_git_blob_9864c7f811c613c3faab876659c6423__25[[#This Row],[Tiempo de permanencia]]-spaces_3iWczBNnn5rbfoUlE0Jd_uploads_git_blob_9864c7f811c613c3faab876659c6423__25[[#This Row],[Tiempo de preparación total]])>0,spaces_3iWczBNnn5rbfoUlE0Jd_uploads_git_blob_9864c7f811c613c3faab876659c6423__25[[#This Row],[Tiempo de permanencia]]-spaces_3iWczBNnn5rbfoUlE0Jd_uploads_git_blob_9864c7f811c613c3faab876659c6423__25[[#This Row],[Tiempo de preparación total]],spaces_3iWczBNnn5rbfoUlE0Jd_uploads_git_blob_9864c7f811c613c3faab876659c6423__25[[#This Row],[Tiempo de permanencia]]-spaces_3iWczBNnn5rbfoUlE0Jd_uploads_git_blob_9864c7f811c613c3faab876659c6423__25[[#This Row],[Tiempo de preparación total]]<0,0)} -> 0.075 | U6: {=_xlfn.IFS(spaces_3iWczBNnn5rbfoUlE0Jd_uploads_git_blob_9864c7f811c613c3faab876659c6423__25[[#This Row],[Tiempo degustación]]=0,"NO PAGADA",spaces_3iWczBNnn5rbfoUlE0Jd_uploads_git_blob_9864c7f811c613c3faab876659c6423__25[[#This Row],[Tiempo degustación]]>0, "PAGADA")} -> PAGADA
A7: 7 | B7: Cliente_965 | C7: 5 | D7: 45017.058 | E7: 45017.147 | F7: Mesero_4 | G7: Cena | H7: Tarjeta de crédito | I7: 26.57 | J7: Libre | K7: 6 | L7: Perú | M7: Plato_8 | N7: =_xlfn.XLOOKUP(spaces_3iWczBNnn5rbfoUlE0Jd_uploads_git_blob_9864c7f811c613c3faab876659c6423__25[[#This Row],[Número de Orden]],Cocinadinamica!B8:B776,Cocinadinamica!C8:C776) -> 28 | O7: =spaces_3iWczBNnn5rbfoUlE0Jd_uploads_git_blob_9864c7f811c613c3faab876659c6423__25[[#This Row],[Hora de Llegada]] -> 45017.058 | P7: =spaces_3iWczBNnn5rbfoUlE0Jd_uploads_git_blob_9864c7f811c613c3faab876659c6423__25[[#This Row],[Hora de Llegada]] -> 45017.058 | Q7: =spaces_3iWczBNnn5rbfoUlE0Jd_uploads_git_blob_9864c7f811c613c3faab876659c6423__25[[#This Row],[Hora de Salida]] -> 45017.147 | R7: {=_xlfn.IFS(spaces_3iWczBNnn5rbfoUlE0Jd_uploads_git_blob_9864c7f811c613c3faab876659c6423__25[[#This Row],[Estado de la Mesa]]="Ocupada",(15/1440)+spaces_3iWczBNnn5rbfoUlE0Jd_uploads_git_blob_9864c7f811c613c3faab876659c6423__25[[#This Row],[Hora de salida2]]-spaces_3iWczBNnn5rbfoUlE0Jd_uploads_git_blob_9864c7f811c613c3faab876659c6423__25[[#This Row],[Hora de llegada2]],spaces_3iWczBNnn5rbfoUlE0Jd_uploads_git_blob_9864c7f811c613c3faab876659c6423__25[[#This Row],[Estado de la Mesa]]<>"Ocupada",spaces_3iWczBNnn5rbfoUlE0Jd_uploads_git_blob_9864c7f811c613c3faab876659c6423__25[[#This Row],[Hora de salida2]]-spaces_3iWczBNnn5rbfoUlE0Jd_uploads_git_blob_9864c7f811c613c3faab876659c6423__25[[#This Row],[Hora de llegada2]])} -> 0.088888889 | S7: =_xlfn.XLOOKUP(spaces_3iWczBNnn5rbfoUlE0Jd_uploads_git_blob_9864c7f811c613c3faab876659c6423__25[[#This Row],[Número de Orden]],Cocinadinamica!E8:E776,Cocinadinamica!F8:F776)/1440 -> 0.0076388889 | T7: {=_xlfn.IFS((spaces_3iWczBNnn5rbfoUlE0Jd_uploads_git_blob_9864c7f811c613c3faab876659c6423__25[[#This Row],[Tiempo de permanencia]]-spaces_3iWczBNnn5rbfoUlE0Jd_uploads_git_blob_9864c7f811c613c3faab876659c6423__25[[#This Row],[Tiempo de preparación total]])>0,spaces_3iWczBNnn5rbfoUlE0Jd_uploads_git_blob_9864c7f811c613c3faab876659c6423__25[[#This Row],[Tiempo de permanencia]]-spaces_3iWczBNnn5rbfoUlE0Jd_uploads_git_blob_9864c7f811c613c3faab876659c6423__25[[#This Row],[Tiempo de preparación total]],spaces_3iWczBNnn5rbfoUlE0Jd_uploads_git_blob_9864c7f811c613c3faab876659c6423__25[[#This Row],[Tiempo de permanencia]]-spaces_3iWczBNnn5rbfoUlE0Jd_uploads_git_blob_9864c7f811c613c3faab876659c6423__25[[#This Row],[Tiempo de preparación total]]<0,0)} -> 0.08125 | U7: {=_xlfn.IFS(spaces_3iWczBNnn5rbfoUlE0Jd_uploads_git_blob_9864c7f811c613c3faab876659c6423__25[[#This Row],[Tiempo degustación]]=0,"NO PAGADA",spaces_3iWczBNnn5rbfoUlE0Jd_uploads_git_blob_9864c7f811c613c3faab876659c6423__25[[#This Row],[Tiempo degustación]]>0, "PAGADA")} -> PAGADA
A8: 17 | B8: Cliente_306 | C8: 6 | D8: 45017.081 | E8: 45017.182 | F8: Mesero_2 | G8: Cena | H8: Tarjeta de crédito | I8: 10.54 | J8: Ocupada | K8: 7 | L8: Venezuela | M8: Plato_15, Plato_19 | N8: =_xlfn.XLOOKUP(spaces_3iWczBNnn5rbfoUlE0Jd_uploads_git_blob_9864c7f811c613c3faab876659c6423__25[[#This Row],[Número de Orden]],Cocinadinamica!B9:B777,Cocinadinamica!C9:C777) -> 68 | O8: =spaces_3iWczBNnn5rbfoUlE0Jd_uploads_git_blob_9864c7f811c613c3faab876659c6423__25[[#This Row],[Hora de Llegada]] -> 45017.081 | P8: =spaces_3iWczBNnn5rbfoUlE0Jd_uploads_git_blob_9864c7f811c613c3faab876659c6423__25[[#This Row],[Hora de Llegada]] -> 45017.081 | Q8: =spaces_3iWczBNnn5rbfoUlE0Jd_uploads_git_blob_9864c7f811c613c3faab876659c6423__25[[#This Row],[Hora de Salida]] -> 45017.182 | R8: {=_xlfn.IFS(spaces_3iWczBNnn5rbfoUlE0Jd_uploads_git_blob_9864c7f811c613c3faab876659c6423__25[[#This Row],[Estado de la Mesa]]="Ocupada",(15/1440)+spaces_3iWczBNnn5rbfoUlE0Jd_uploads_git_blob_9864c7f811c613c3faab876659c6423__25[[#This Row],[Hora de salida2]]-spaces_3iWczBNnn5rbfoUlE0Jd_uploads_git_blob_9864c7f811c613c3faab876659c6423__25[[#This Row],[Hora de llegada2]],spaces_3iWczBNnn5rbfoUlE0Jd_uploads_git_blob_9864c7f811c613c3faab876659c6423__25[[#This Row],[Estado de la Mesa]]<>"Ocupada",spaces_3iWczBNnn5rbfoUlE0Jd_uploads_git_blob_9864c7f811c613c3faab876659c6423__25[[#This Row],[Hora de salida2]]-spaces_3iWczBNnn5rbfoUlE0Jd_uploads_git_blob_9864c7f811c613c3faab876659c6423__25[[#This Row],[Hora de llegada2]])} -> 0.11111111 | S8: =_xlfn.XLOOKUP(spaces_3iWczBNnn5rbfoUlE0Jd_uploads_git_blob_9864c7f811c613c3faab876659c6423__25[[#This Row],[Número de Orden]],Cocinadinamica!E9:E777,Cocinadinamica!F9:F777)/1440 -> 0.028472222 | T8: {=_xlfn.IFS((spaces_3iWczBNnn5rbfoUlE0Jd_uploads_git_blob_9864c7f811c613c3faab876659c6423__25[[#This Row],[Tiempo de permanencia]]-spaces_3iWczBNnn5rbfoUlE0Jd_uploads_git_blob_9864c7f811c613c3faab876659c6423__25[[#This Row],[Tiempo de preparación total]])>0,spaces_3iWczBNnn5rbfoUlE0Jd_uploads_git_blob_9864c7f811c613c3faab876659c6423__25[[#This Row],[Tiempo de permanencia]]-spaces_3iWczBNnn5rbfoUlE0Jd_uploads_git_blob_9864c7f811c613c3faab876659c6423__25[[#This Row],[Tiempo de preparación total]],spaces_3iWczBNnn5rbfoUlE0Jd_uploads_git_blob_9864c7f811c613c3faab876659c6423__25[[#This Row],[Tiempo de permanencia]]-spaces_3iWczBNnn5rbfoUlE0Jd_uploads_git_blob_9864c7f811c613c3faab876659c6423__25[[#This Row],[Tiempo de preparación total]]<0,0)} -> 0.082638889 | U8: {=_xlfn.IFS(spaces_3iWczBNnn5rbfoUlE0Jd_uploads_git_blob_9864c7f811c613c3faab876659c6423__25[[#This Row],[Tiempo degustación]]=0,"NO PAGADA",spaces_3iWczBNnn5rbfoUlE0Jd_uploads_git_blob_9864c7f811c613c3faab876659c6423__25[[#This Row],[Tiempo degustación]]>0, "PAGADA")} -> PAGADA
A9: 11 | B9: Cliente_974 | C9: 1 | D9: 45017.091 | E9: 45017.201 | F9: Mesero_2 | G9: Desayuno | H9: Tarjeta de crédito | I9: 49.18 | J9: Reservada | K9: 8 | L9: Paraguay | M9: Plato_5, Plato_16, Plato_20 | N9: =_xlfn.XLOOKUP(spaces_3iWczBNnn5rbfoUlE0Jd_uploads_git_blob_9864c7f811c613c3faab876659c6423__25[[#This Row],[Número de Orden]],Cocinadinamica!B10:B778,Cocinadinamica!C10:C778) -> 96 | O9: =spaces_3iWczBNnn5rbfoUlE0Jd_uploads_git_blob_9864c7f811c613c3faab876659c6423__25[[#This Row],[Hora de Llegada]] -> 45017.091 | P9: =spaces_3iWczBNnn5rbfoUlE0Jd_uploads_git_blob_9864c7f811c613c3faab876659c6423__25[[#This Row],[Hora de Llegada]] -> 45017.091 | Q9: =spaces_3iWczBNnn5rbfoUlE0Jd_uploads_git_blob_9864c7f811c613c3faab876659c6423__25[[#This Row],[Hora de Salida]] -> 45017.201 | R9: {=_xlfn.IFS(spaces_3iWczBNnn5rbfoUlE0Jd_uploads_git_blob_9864c7f811c613c3faab876659c6423__25[[#This Row],[Estado de la Mesa]]="Ocupada",(15/1440)+spaces_3iWczBNnn5rbfoUlE0Jd_uploads_git_blob_9864c7f811c613c3faab876659c6423__25[[#This Row],[Hora de salida2]]-spaces_3iWczBNnn5rbfoUlE0Jd_uploads_git_blob_9864c7f811c613c3faab876659c6423__25[[#This Row],[Hora de llegada2]],spaces_3iWczBNnn5rbfoUlE0Jd_uploads_git_blob_9864c7f811c613c3faab876659c6423__25[[#This Row],[Estado de la Mesa]]<>"Ocupada",spaces_3iWczBNnn5rbfoUlE0Jd_uploads_git_blob_9864c7f811c613c3faab876659c6423__25[[#This Row],[Hora de salida2]]-spaces_3iWczBNnn5rbfoUlE0Jd_uploads_git_blob_9864c7f811c613c3faab876659c6423__25[[#This Row],[Hora de llegada2]])} -> 0.10972222 | S9: =_xlfn.XLOOKUP(spaces_3iWczBNnn5rbfoUlE0Jd_uploads_git_blob_9864c7f811c613c3faab876659c6423__25[[#This Row],[Número de Orden]],Cocinadinamica!E10:E778,Cocinadinamica!F10:F778)/1440 -> 0.038194444 | T9: {=_xlfn.IFS((spaces_3iWczBNnn5rbfoUlE0Jd_uploads_git_blob_9864c7f811c613c3faab876659c6423__25[[#This Row],[Tiempo de permanencia]]-spaces_3iWczBNnn5rbfoUlE0Jd_uploads_git_blob_9864c7f811c613c3faab876659c6423__25[[#This Row],[Tiempo de preparación total]])>0,spaces_3iWczBNnn5rbfoUlE0Jd_uploads_git_blob_9864c7f811c613c3faab876659c6423__25[[#This Row],[Tiempo de permanencia]]-spaces_3iWczBNnn5rbfoUlE0Jd_uploads_git_blob_9864c7f811c613c3faab876659c6423__25[[#This Row],[Tiempo de preparación total]],spaces_3iWczBNnn5rbfoUlE0Jd_uploads_git_blob_9864c7f811c613c3faab876659c6423__25[[#This Row],[Tiempo de permanencia]]-spaces_3iWczBNnn5rbfoUlE0Jd_uploads_git_blob_9864c7f811c613c3faab876659c6423__25[[#This Row],[Tiempo de preparación total]]<0,0)} -> 0.071527778 | U9: {=_xlfn.IFS(spaces_3iWczBNnn5rbfoUlE0Jd_uploads_git_blob_9864c7f811c613c3faab876659c6423__25[[#This Row],[Tiempo degustación]]=0,"NO PAGADA",spaces_3iWczBNnn5rbfoUlE0Jd_uploads_git_blob_9864c7f811c613c3faab876659c6423__25[[#This Row],[Tiempo degustación]]>0, "PAGADA")} -> PAGADA
A10: 15 | B10: Cliente_740 | C10: 5 | D10: 45017.085 | E10: 45017.184 | F10: Mesero_2 | G10: Almuerzo | H10: Tarjeta de débito | I10: 46.85 | J10: Libre | K10: 9 | L10: Bolivia | M10: Plato_2, Plato_7, Plato_12, Plato_15 | N10: =_xlfn.XLOOKUP(spaces_3iWczBNnn5rbfoUlE0Jd_uploads_git_blob_9864c7f811c613c3faab876659c6423__25[[#This Row],[Número de Orden]],Cocinadinamica!B11:B779,Cocinadinamica!C11:C779) -> 69 | O10: =spaces_3iWczBNnn5rbfoUlE0Jd_uploads_git_blob_9864c7f811c613c3faab876659c6423__25[[#This Row],[Hora de Llegada]] -> 45017.085 | P10: =spaces_3iWczBNnn5rbfoUlE0Jd_uploads_git_blob_9864c7f811c613c3faab876659c6423__25[[#This Row],[Hora de Llegada]] -> 45017.085 | Q10: =spaces_3iWczBNnn5rbfoUlE0Jd_uploads_git_blob_9864c7f811c613c3faab876659c6423__25[[#This Row],[Hora de Salida]] -> 45017.184 | R10: {=_xlfn.IFS(spaces_3iWczBNnn5rbfoUlE0Jd_uploads_git_blob_9864c7f811c613c3faab876659c6423__25[[#This Row],[Estado de la Mesa]]="Ocupada",(15/1440)+spaces_3iWczBNnn5rbfoUlE0Jd_uploads_git_blob_9864c7f811c613c3faab876659c6423__25[[#This Row],[Hora de salida2]]-spaces_3iWczBNnn5rbfoUlE0Jd_uploads_git_blob_9864c7f811c613c3faab876659c6423__25[[#This Row],[Hora de llegada2]],spaces_3iWczBNnn5rbfoUlE0Jd_uploads_git_blob_9864c7f811c613c3faab876659c6423__25[[#This Row],[Estado de la Mesa]]<>"Ocupada",spaces_3iWczBNnn5rbfoUlE0Jd_uploads_git_blob_9864c7f811c613c3faab876659c6423__25[[#This Row],[Hora de salida2]]-spaces_3iWczBNnn5rbfoUlE0Jd_uploads_git_blob_9864c7f811c613c3faab876659c6423__25[[#This Row],[Hora de llegada2]])} -> 0.098611111 | S10: =_xlfn.XLOOKUP(spaces_3iWczBNnn5rbfoUlE0Jd_uploads_git_blob_9864c7f811c613c3faab876659c6423__25[[#This Row],[Número de Orden]],Cocinadinamica!E11:E779,Cocinadinamica!F11:F779)/1440 -> 0.10138889 | T10: {=_xlfn.IFS((spaces_3iWczBNnn5rbfoUlE0Jd_uploads_git_blob_9864c7f811c613c3faab876659c6423__25[[#This Row],[Tiempo de permanencia]]-spaces_3iWczBNnn5rbfoUlE0Jd_uploads_git_blob_9864c7f811c613c3faab876659c6423__25[[#This Row],[Tiempo de preparación total]])>0,spaces_3iWczBNnn5rbfoUlE0Jd_uploads_git_blob_9864c7f811c613c3faab876659c6423__25[[#This Row],[Tiempo de permanencia]]-spaces_3iWczBNnn5rbfoUlE0Jd_uploads_git_blob_9864c7f811c613c3faab876659c6423__25[[#This Row],[Tiempo de preparación total]],spaces_3iWczBNnn5rbfoUlE0Jd_uploads_git_blob_9864c7f811c613c3faab876659c6423__25[[#This Row],[Tiempo de permanencia]]-spaces_3iWczBNnn5rbfoUlE0Jd_uploads_git_blob_9864c7f811c613c3faab876659c6423__25[[#This Row],[Tiempo de preparación total]]<0,0)} -> 0 | U10: {=_xlfn.IFS(spaces_3iWczBNnn5rbfoUlE0Jd_uploads_git_blob_9864c7f811c613c3faab876659c6423__25[[#This Row],[Tiempo degustación]]=0,"NO PAGADA",spaces_3iWczBNnn5rbfoUlE0Jd_uploads_git_blob_9864c7f811c613c3faab876659c6423__25[[#This Row],[Tiempo degustación]]>0, "PAGADA")} -> NO PAGADA
A11: 17 | B11: Cliente_33 | C11: 1 | D11: 45017.001 | E11: 45017.078 | F11: Mesero_4 | G11: Almuerzo | H11: Tarjeta de crédito | I11: 16.6 | J11: Ocupada | K11: 10 | L11: Uruguay | M11: Plato_18, Plato_20 | N11: =_xlfn.XLOOKUP(spaces_3iWczBNnn5rbfoUlE0Jd_uploads_git_blob_9864c7f811c613c3faab876659c6423__25[[#This Row],[Número de Orden]],Cocinadinamica!B12:B780,Cocinadinamica!C12:C780) -> 58 | O11: =spaces_3iWczBNnn5rbfoUlE0Jd_uploads_git_blob_9864c7f811c613c3faab876659c6423__25[[#This Row],[Hora de Llegada]] -> 45017.001 | P11: =spaces_3iWczBNnn5rbfoUlE0Jd_uploads_git_blob_9864c7f811c613c3faab876659c6423__25[[#This Row],[Hora de Llegada]] -> 45017.001 | Q11: =spaces_3iWczBNnn5rbfoUlE0Jd_uploads_git_blob_9864c7f811c613c3faab876659c6423__25[[#This Row],[Hora de Salida]] -> 45017.078 | R11: {=_xlfn.IFS(spaces_3iWczBNnn5rbfoUlE0Jd_uploads_git_blob_9864c7f811c613c3faab876659c6423__25[[#This Row],[Estado de la Mesa]]="Ocupada",(15/1440)+spaces_3iWczBNnn5rbfoUlE0Jd_uploads_git_blob_9864c7f811c613c3faab876659c6423__25[[#This Row],[Hora de salida2]]-spaces_3iWczBNnn5rbfoUlE0Jd_uploads_git_blob_9864c7f811c613c3faab876659c6423__25[[#This Row],[Hora de llegada2]],spaces_3iWczBNnn5rbfoUlE0Jd_uploads_git_blob_9864c7f811c613c3faab876659c6423__25[[#This Row],[Estado de la Mesa]]<>"Ocupada",spaces_3iWczBNnn5rbfoUlE0Jd_uploads_git_blob_9864c7f811c613c3faab876659c6423__25[[#This Row],[Hora de salida2]]-spaces_3iWczBNnn5rbfoUlE0Jd_uploads_git_blob_9864c7f811c613c3faab876659c6423__25[[#This Row],[Hora de llegada2]])} -> 0.0875 | S11: =_xlfn.XLOOKUP(spaces_3iWczBNnn5rbfoUlE0Jd_uploads_git_blob_9864c7f811c613c3faab876659c6423__25[[#This Row],[Número de Orden]],Cocinadinamica!E12:E780,Cocinadinamica!F12:F780)/1440 -> 0.020138889 | T11: {=_xlfn.IFS((spaces_3iWczBNnn5rbfoUlE0Jd_uploads_git_blob_9864c7f811c613c3faab876659c6423__25[[#This Row],[Tiempo de permanencia]]-spaces_3iWczBNnn5rbfoUlE0Jd_uploads_git_blob_9864c7f811c613c3faab876659c6423__25[[#This Row],[Tiempo de preparación total]])>0,spaces_3iWczBNnn5rbfoUlE0Jd_uploads_git_blob_9864c7f811c613c3faab876659c6423__25[[#This Row],[Tiempo de permanencia]]-spaces_3iWczBNnn5rbfoUlE0Jd_uploads_git_blob_9864c7f811c613c3faab876659c6423__25[[#This Row],[Tiempo de preparación total]],spaces_3iWczBNnn5rbfoUlE0Jd_uploads_git_blob_9864c7f811c613c3faab876659c6423__25[[#This Row],[Tiempo de permanencia]]-spaces_3iWczBNnn5rbfoUlE0Jd_uploads_git_blob_9864c7f811c613c3faab876659c6423__25[[#This Row],[Tiempo de preparación total]]<0,0)} -> 0.067361111 | U11: {=_xlfn.IFS(spaces_3iWczBNnn5rbfoUlE0Jd_uploads_git_blob_9864c7f811c613c3faab876659c6423__25[[#This Row],[Tiempo degustación]]=0,"NO PAGADA",spaces_3iWczBNnn5rbfoUlE0Jd_uploads_git_blob_9864c7f811c613c3faab876659c6423__25[[#This Row],[Tiempo degustación]]>0, "PAGADA")} -> PAGADA
A12: 14 | B12: Cliente_881 | C12: 1 | D12: 45017.157 | E12: 45017.273 | F12: Mesero_1 | G12: Almuerzo | H12: Tarjeta de crédito | I12: 32.89 | J12: Libre | K12: 11 | L12: Perú | M12: Plato_16, Plato_2 | N12: =_xlfn.XLOOKUP(spaces_3iWczBNnn5rbfoUlE0Jd_uploads_git_blob_9864c7f811c613c3faab876659c6423__25[[#This Row],[Número de Orden]],Cocinadinamica!B13:B781,Cocinadinamica!C13:C781) -> 36 | O12: =spaces_3iWczBNnn5rbfoUlE0Jd_uploads_git_blob_9864c7f811c613c3faab876659c6423__25[[#This Row],[Hora de Llegada]] -> 45017.157 | P12: =spaces_3iWczBNnn5rbfoUlE0Jd_uploads_git_blob_9864c7f811c613c3faab876659c6423__25[[#This Row],[Hora de Llegada]] -> 45017.157 | Q12: =spaces_3iWczBNnn5rbfoUlE0Jd_uploads_git_blob_9864c7f811c613c3faab876659c6423__25[[#This Row],[Hora de Salida]] -> 45017.273 | R12: {=_xlfn.IFS(spaces_3iWczBNnn5rbfoUlE0Jd_uploads_git_blob_9864c7f811c613c3faab876659c6423__25[[#This Row],[Estado de la Mesa]]="Ocupada",(15/1440)+spaces_3iWczBNnn5rbfoUlE0Jd_uploads_git_blob_9864c7f811c613c3faab876659c6423__25[[#This Row],[Hora de salida2]]-spaces_3iWczBNnn5rbfoUlE0Jd_uploads_git_blob_9864c7f811c613c3faab876659c6423__25[[#This Row],[Hora de llegada2]],spaces_3iWczBNnn5rbfoUlE0Jd_uploads_git_blob_9864c7f811c613c3faab876659c6423__25[[#This Row],[Estado de la Mesa]]<>"Ocupada",spaces_3iWczBNnn5rbfoUlE0Jd_uploads_git_blob_9864c7f811c613c3faab876659c6423__25[[#This Row],[Hora de salida2]]-spaces_3iWczBNnn5rbfoUlE0Jd_uploads_git_blob_9864c7f811c613c3faab876659c6423__25[[#This Row],[Hora de llegada2]])} -> 0.11597222 | S12: =_xlfn.XLOOKUP(spaces_3iWczBNnn5rbfoUlE0Jd_uploads_git_blob_9864c7f811c613c3faab876659c6423__25[[#This Row],[Número de Orden]],Cocinadinamica!E13:E781,Cocinadinamica!F13:F781)/1440 -> 0.038888889 | T12: {=_xlfn.IFS((spaces_3iWczBNnn5rbfoUlE0Jd_uploads_git_blob_9864c7f811c613c3faab876659c6423__25[[#This Row],[Tiempo de permanencia]]-spaces_3iWczBNnn5rbfoUlE0Jd_uploads_git_blob_9864c7f811c613c3faab876659c6423__25[[#This Row],[Tiempo de preparación total]])>0,spaces_3iWczBNnn5rbfoUlE0Jd_uploads_git_blob_9864c7f811c613c3faab876659c6423__25[[#This Row],[Tiempo de permanencia]]-spaces_3iWczBNnn5rbfoUlE0Jd_uploads_git_blob_9864c7f811c613c3faab876659c6423__25[[#This Row],[Tiempo de preparación total]],spaces_3iWczBNnn5rbfoUlE0Jd_uploads_git_blob_9864c7f811c613c3faab876659c6423__25[[#This Row],[Tiempo de permanencia]]-spaces_3iWczBNnn5rbfoUlE0Jd_uploads_git_blob_9864c7f811c613c3faab876659c6423__25[[#This Row],[Tiempo de preparación total]]<0,0)} -> 0.077083333 | U12: {=_xlfn.IFS(spaces_3iWczBNnn5rbfoUlE0Jd_uploads_git_blob_9864c7f811c613c3faab876659c6423__25[[#This Row],[Tiempo degustación]]=0,"NO PAGADA",spaces_3iWczBNnn5rbfoUlE0Jd_uploads_git_blob_9864c7f811c613c3faab876659c6423__25[[#This Row],[Tiempo degustación]]>0, "PAGADA")} -> PAGADA
A13: 14 | B13: Cliente_890 | C13: 6 | D13: 45017.003 | E13: 45017.141 | F13: Mesero_4 | G13: Cena | H13: Tarjeta de crédito | I13: 45.27 | J13: Ocupada | K13: 12 | L13: Colombia | M13: Plato_16, Plato_19, Plato_8, Plato_20 | N13: =_xlfn.XLOOKUP(spaces_3iWczBNnn5rbfoUlE0Jd_uploads_git_blob_9864c7f811c613c3faab876659c6423__25[[#This Row],[Número de Orden]],Cocinadinamica!B14:B782,Cocinadinamica!C14:C782) -> 127 | O13: =spaces_3iWczBNnn5rbfoUlE0Jd_uploads_git_blob_9864c7f811c613c3faab876659c6423__25[[#This Row],[Hora de Llegada]] -> 45017.003 | P13: =spaces_3iWczBNnn5rbfoUlE0Jd_uploads_git_blob_9864c7f811c613c3faab876659c6423__25[[#This Row],[Hora de Llegada]] -> 45017.003 | Q13: =spaces_3iWczBNnn5rbfoUlE0Jd_uploads_git_blob_9864c7f811c613c3faab876659c6423__25[[#This Row],[Hora de Salida]] -> 45017.141 | R13: {=_xlfn.IFS(spaces_3iWczBNnn5rbfoUlE0Jd_uploads_git_blob_9864c7f811c613c3faab876659c6423__25[[#This Row],[Estado de la Mesa]]="Ocupada",(15/1440)+spaces_3iWczBNnn5rbfoUlE0Jd_uploads_git_blob_9864c7f811c613c3faab876659c6423__25[[#This Row],[Hora de salida2]]-spaces_3iWczBNnn5rbfoUlE0Jd_uploads_git_blob_9864c7f811c613c3faab876659c6423__25[[#This Row],[Hora de llegada2]],spaces_3iWczBNnn5rbfoUlE0Jd_uploads_git_blob_9864c7f811c613c3faab876659c6423__25[[#This Row],[Estado de la Mesa]]<>"Ocupada",spaces_3iWczBNnn5rbfoUlE0Jd_uploads_git_blob_9864c7f811c613c3faab876659c6423__25[[#This Row],[Hora de salida2]]-spaces_3iWczBNnn5rbfoUlE0Jd_uploads_git_blob_9864c7f811c613c3faab876659c6423__25[[#This Row],[Hora de llegada2]])} -> 0.14861111 | S13: =_xlfn.XLOOKUP(spaces_3iWczBNnn5rbfoUlE0Jd_uploads_git_blob_9864c7f811c613c3faab876659c6423__25[[#This Row],[Número de Orden]],Cocinadinamica!E14:E782,Cocinadinamica!F14:F782)/1440 -> 0.065972222 | T13: {=_xlfn.IFS((spaces_3iWczBNnn5rbfoUlE0Jd_uploads_git_blob_9864c7f811c613c3faab876659c6423__25[[#This Row],[Tiempo de permanencia]]-spaces_3iWczBNnn5rbfoUlE0Jd_uploads_git_blob_9864c7f811c613c3faab876659c6423__25[[#This Row],[Tiempo de preparación total]])>0,spaces_3iWczBNnn5rbfoUlE0Jd_uploads_git_blob_9864c7f811c613c3faab876659c6423__25[[#This Row],[Tiempo de permanencia]]-spaces_3iWczBNnn5rbfoUlE0Jd_uploads_git_blob_9864c7f811c613c3faab876659c6423__25[[#This Row],[Tiempo de preparación total]],spaces_3iWczBNnn5rbfoUlE0Jd_uploads_git_blob_9864c7f811c613c3faab876659c6423__25[[#This Row],[Tiempo de permanencia]]-spaces_3iWczBNnn5rbfoUlE0Jd_uploads_git_blob_9864c7f811c613c3faab876659c6423__25[[#This Row],[Tiempo de preparación total]]<0,0)} -> 0.082638889 | U13: {=_xlfn.IFS(spaces_3iWczBNnn5rbfoUlE0Jd_uploads_git_blob_9864c7f811c613c3faab876659c6423__25[[#This Row],[Tiempo degustación]]=0,"NO PAGADA",spaces_3iWczBNnn5rbfoUlE0Jd_uploads_git_blob_9864c7f811c613c3faab876659c6423__25[[#This Row],[Tiempo degustación]]>0, "PAGADA")} -> PAGADA
A14: 2 | B14: Cliente_873 | C14: 1 | D14: 45017.131 | E14: 45017.231 | F14: Mesero_5 | G14: Almuerzo | H14: Efectivo | I14: 22.06 | J14: Ocupada | K14: 13 | L14: Brasil | M14: Plato_9 | N14: =_xlfn.XLOOKUP(spaces_3iWczBNnn5rbfoUlE0Jd_uploads_git_blob_9864c7f811c613c3faab876659c6423__25[[#This Row],[Número de Orden]],Cocinadinamica!B15:B783,Cocinadinamica!C15:C783) -> 36 | O14: =spaces_3iWczBNnn5rbfoUlE0Jd_uploads_git_blob_9864c7f811c613c3faab876659c6423__25[[#This Row],[Hora de Llegada]] -> 45017.131 | P14: =spaces_3iWczBNnn5rbfoUlE0Jd_uploads_git_blob_9864c7f811c613c3faab876659c6423__25[[#This Row],[Hora de Llegada]] -> 45017.131 | Q14: =spaces_3iWczBNnn5rbfoUlE0Jd_uploads_git_blob_9864c7f811c613c3faab876659c6423__25[[#This Row],[Hora de Salida]] -> 45017.231 | R14: {=_xlfn.IFS(spaces_3iWczBNnn5rbfoUlE0Jd_uploads_git_blob_9864c7f811c613c3faab876659c6423__25[[#This Row],[Estado de la Mesa]]="Ocupada",(15/1440)+spaces_3iWczBNnn5rbfoUlE0Jd_uploads_git_blob_9864c7f811c613c3faab876659c6423__25[[#This Row],[Hora de salida2]]-spaces_3iWczBNnn5rbfoUlE0Jd_uploads_git_blob_9864c7f811c613c3faab876659c6423__25[[#This Row],[Hora de llegada2]],spaces_3iWczBNnn5rbfoUlE0Jd_uploads_git_blob_9864c7f811c613c3faab876659c6423__25[[#This Row],[Estado de la Mesa]]<>"Ocupada",spaces_3iWczBNnn5rbfoUlE0Jd_uploads_git_blob_9864c7f811c613c3faab876659c6423__25[[#This Row],[Hora de salida2]]-spaces_3iWczBNnn5rbfoUlE0Jd_uploads_git_blob_9864c7f811c613c3faab876659c6423__25[[#This Row],[Hora de llegada2]])} -> 0.10972222 | S14: =_xlfn.XLOOKUP(spaces_3iWczBNnn5rbfoUlE0Jd_uploads_git_blob_9864c7f811c613c3faab876659c6423__25[[#This Row],[Número de Orden]],Cocinadinamica!E15:E783,Cocinadinamica!F15:F783)/1440 -> 0.040972222 | T14: {=_xlfn.IFS((spaces_3iWczBNnn5rbfoUlE0Jd_uploads_git_blob_9864c7f811c613c3faab876659c6423__25[[#This Row],[Tiempo de permanencia]]-spaces_3iWczBNnn5rbfoUlE0Jd_uploads_git_blob_9864c7f811c613c3faab876659c6423__25[[#This Row],[Tiempo de preparación total]])>0,spaces_3iWczBNnn5rbfoUlE0Jd_uploads_git_blob_9864c7f811c613c3faab876659c6423__25[[#This Row],[Tiempo de permanencia]]-spaces_3iWczBNnn5rbfoUlE0Jd_uploads_git_blob_9864c7f811c613c3faab876659c6423__25[[#This Row],[Tiempo de preparación total]],spaces_3iWczBNnn5rbfoUlE0Jd_uploads_git_blob_9864c7f811c613c3faab876659c6423__25[[#This Row],[Tiempo de permanencia]]-spaces_3iWczBNnn5rbfoUlE0Jd_uploads_git_blob_9864c7f811c613c3faab876659c6423__25[[#This Row],[Tiempo de preparación total]]<0,0)} -> 0.06875 | U14: {=_xlfn.IFS(spaces_3iWczBNnn5rbfoUlE0Jd_uploads_git_blob_9864c7f811c613c3faab876659c6423__25[[#This Row],[Tiempo degustación]]=0,"NO PAGADA",spaces_3iWczBNnn5rbfoUlE0Jd_uploads_git_blob_9864c7f811c613c3faab876659c6423__25[[#This Row],[Tiempo degustación]]>0, "PAGADA")} -> PAGADA
A15: 16 | B15: Cliente_780 | C15: 6 | D15: 45017.012 | E15: 45017.082 | F15: Mesero_2 | G15: Almuerzo | H15: Efectivo | I15: 48.76 | J15: Libre | K15: 14 | L15: Perú | M15: Plato_3, Plato_11, Plato_14, Plato_2 | N15: =_xlfn.XLOOKUP(spaces_3iWczBNnn5rbfoUlE0Jd_uploads_git_blob_9864c7f811c613c3faab876659c6423__25[[#This Row],[Número de Orden]],Cocinadinamica!B16:B784,Cocinadinamica!C16:C784) -> 51 | O15: =spaces_3iWczBNnn5rbfoUlE0Jd_uploads_git_blob_9864c7f811c613c3faab876659c6423__25[[#This Row],[Hora de Llegada]] -> 45017.012 | P15: =spaces_3iWczBNnn5rbfoUlE0Jd_uploads_git_blob_9864c7f811c613c3faab876659c6423__25[[#This Row],[Hora de Llegada]] -> 45017.012 | Q15: =spaces_3iWczBNnn5rbfoUlE0Jd_uploads_git_blob_9864c7f811c613c3faab876659c6423__25[[#This Row],[Hora de Salida]] -> 45017.082 | R15: {=_xlfn.IFS(spaces_3iWczBNnn5rbfoUlE0Jd_uploads_git_blob_9864c7f811c613c3faab876659c6423__25[[#This Row],[Estado de la Mesa]]="Ocupada",(15/1440)+spaces_3iWczBNnn5rbfoUlE0Jd_uploads_git_blob_9864c7f811c613c3faab876659c6423__25[[#This Row],[Hora de salida2]]-spaces_3iWczBNnn5rbfoUlE0Jd_uploads_git_blob_9864c7f811c613c3faab876659c6423__25[[#This Row],[Hora de llegada2]],spaces_3iWczBNnn5rbfoUlE0Jd_uploads_git_blob_9864c7f811c613c3faab876659c6423__25[[#This Row],[Estado de la Mesa]]<>"Ocupada",spaces_3iWczBNnn5rbfoUlE0Jd_uploads_git_blob_9864c7f811c613c3faab876659c6423__25[[#This Row],[Hora de salida2]]-spaces_3iWczBNnn5rbfoUlE0Jd_uploads_git_blob_9864c7f811c613c3faab876659c6423__25[[#This Row],[Hora de llegada2]])} -> 0.069444444 | S15: =_xlfn.XLOOKUP(spaces_3iWczBNnn5rbfoUlE0Jd_uploads_git_blob_9864c7f811c613c3faab876659c6423__25[[#This Row],[Número de Orden]],Cocinadinamica!E16:E784,Cocinadinamica!F16:F784)/1440 -> 0.10694444 | T15: {=_xlfn.IFS((spaces_3iWczBNnn5rbfoUlE0Jd_uploads_git_blob_9864c7f811c613c3faab876659c6423__25[[#This Row],[Tiempo de permanencia]]-spaces_3iWczBNnn5rbfoUlE0Jd_uploads_git_blob_9864c7f811c613c3faab876659c6423__25[[#This Row],[Tiempo de preparación total]])>0,spaces_3iWczBNnn5rbfoUlE0Jd_uploads_git_blob_9864c7f811c613c3faab876659c6423__25[[#This Row],[Tiempo de permanencia]]-spaces_3iWczBNnn5rbfoUlE0Jd_uploads_git_blob_9864c7f811c613c3faab876659c6423__25[[#This Row],[Tiempo de preparación total]],spaces_3iWczBNnn5rbfoUlE0Jd_uploads_git_blob_9864c7f811c613c3faab876659c6423__25[[#This Row],[Tiempo de permanencia]]-spaces_3iWczBNnn5rbfoUlE0Jd_uploads_git_blob_9864c7f811c613c3faab876659c6423__25[[#This Row],[Tiempo de preparación total]]<0,0)} -> 0 | U15: {=_xlfn.IFS(spaces_3iWczBNnn5rbfoUlE0Jd_uploads_git_blob_9864c7f811c613c3faab876659c6423__25[[#This Row],[Tiempo degustación]]=0,"NO PAGADA",spaces_3iWczBNnn5rbfoUlE0Jd_uploads_git_blob_9864c7f811c613c3faab876659c6423__25[[#This Row],[Tiempo degustación]]>0, "PAGADA")} -> NO PAGADA
A16: 6 | B16: Cliente_728 | C16: 4 | D16: 45017.142 | E16: 45017.208 | F16: Mesero_1 | G16: Desayuno | H16: Tarjeta de crédito | I16: 28.77 | J16: Ocupada | K16: 15 | L16: Uruguay | M16: Plato_16, Plato_13, Plato_8 | N16: =_xlfn.XLOOKUP(spaces_3iWczBNnn5rbfoUlE0Jd_uploads_git_blob_9864c7f811c613c3faab876659c6423__25[[#This Row],[Número de Orden]],Cocinadinamica!B17:B785,Cocinadinamica!C17:C785) -> 90 | O16: =spaces_3iWczBNnn5rbfoUlE0Jd_uploads_git_blob_9864c7f811c613c3faab876659c6423__25[[#This Row],[Hora de Llegada]] -> 45017.142 | P16: =spaces_3iWczBNnn5rbfoUlE0Jd_uploads_git_blob_9864c7f811c613c3faab876659c6423__25[[#This Row],[Hora de Llegada]] -> 45017.142 | Q16: =spaces_3iWczBNnn5rbfoUlE0Jd_uploads_git_blob_9864c7f811c613c3faab876659c6423__25[[#This Row],[Hora de Salida]] -> 45017.208 | R16: {=_xlfn.IFS(spaces_3iWczBNnn5rbfoUlE0Jd_uploads_git_blob_9864c7f811c613c3faab876659c6423__25[[#This Row],[Estado de la Mesa]]="Ocupada",(15/1440)+spaces_3iWczBNnn5rbfoUlE0Jd_uploads_git_blob_9864c7f811c613c3faab876659c6423__25[[#This Row],[Hora de salida2]]-spaces_3iWczBNnn5rbfoUlE0Jd_uploads_git_blob_9864c7f811c613c3faab876659c6423__25[[#This Row],[Hora de llegada2]],spaces_3iWczBNnn5rbfoUlE0Jd_uploads_git_blob_9864c7f811c613c3faab876659c6423__25[[#This Row],[Estado de la Mesa]]<>"Ocupada",spaces_3iWczBNnn5rbfoUlE0Jd_uploads_git_blob_9864c7f811c613c3faab876659c6423__25[[#This Row],[Hora de salida2]]-spaces_3iWczBNnn5rbfoUlE0Jd_uploads_git_blob_9864c7f811c613c3faab876659c6423__25[[#This Row],[Hora de llegada2]])} -> 0.076388889 | S16: =_xlfn.XLOOKUP(spaces_3iWczBNnn5rbfoUlE0Jd_uploads_git_blob_9864c7f811c613c3faab876659c6423__25[[#This Row],[Número de Orden]],Cocinadinamica!E17:E785,Cocinadinamica!F17:F785)/1440 -> 0.071527778 | T16: {=_xlfn.IFS((spaces_3iWczBNnn5rbfoUlE0Jd_uploads_git_blob_9864c7f811c613c3faab876659c6423__25[[#This Row],[Tiempo de permanencia]]-spaces_3iWczBNnn5rbfoUlE0Jd_uploads_git_blob_9864c7f811c613c3faab876659c6423__25[[#This Row],[Tiempo de preparación total]])>0,spaces_3iWczBNnn5rbfoUlE0Jd_uploads_git_blob_9864c7f811c613c3faab876659c6423__25[[#This Row],[Tiempo de permanencia]]-spaces_3iWczBNnn5rbfoUlE0Jd_uploads_git_blob_9864c7f811c613c3faab876659c6423__25[[#This Row],[Tiempo de preparación total]],spaces_3iWczBNnn5rbfoUlE0Jd_uploads_git_blob_9864c7f811c613c3faab876659c6423__25[[#This Row],[Tiempo de permanencia]]-spaces_3iWczBNnn5rbfoUlE0Jd_uploads_git_blob_9864c7f811c613c3faab876659c6423__25[[#This Row],[Tiempo de preparación total]]<0,0)} -> 0.0048611111 | U16: {=_xlfn.IFS(spaces_3iWczBNnn5rbfoUlE0Jd_uploads_git_blob_9864c7f811c613c3faab876659c6423__25[[#This Row],[Tiempo degustación]]=0,"NO PAGADA",spaces_3iWczBNnn5rbfoUlE0Jd_uploads_git_blob_9864c7f811c613c3faab876659c6423__25[[#This Row],[Tiempo degustación]]>0, "PAGADA")} -> PAGADA
A17: 20 | B17: Cliente_175 | C17: 5 | D17: 45017.105 | E17: 45017.183 | F17: Mesero_4 | G17: Almuerzo | H17: Efectivo | I17: 3.79 | J17: Reservada | K17: 16 | L17: Bolivia | M17: Plato_16 | N17: =_xlfn.XLOOKUP(spaces_3iWczBNnn5rbfoUlE0Jd_uploads_git_blob_9864c7f811c613c3faab876659c6423__25[[#This Row],[Número de Orden]],Cocinadinamica!B18:B786,Cocinadinamica!C18:C786) -> 12 | O17: =spaces_3iWczBNnn5rbfoUlE0Jd_uploads_git_blob_9864c7f811c613c3faab876659c6423__25[[#This Row],[Hora de Llegada]] -> 45017.105 | P17: =spaces_3iWczBNnn5rbfoUlE0Jd_uploads_git_blob_9864c7f811c613c3faab876659c6423__25[[#This Row],[Hora de Llegada]] -> 45017.105 | Q17: =spaces_3iWczBNnn5rbfoUlE0Jd_uploads_git_blob_9864c7f811c613c3faab876659c6423__25[[#This Row],[Hora de Salida]] -> 45017.183 | R17: {=_xlfn.IFS(spaces_3iWczBNnn5rbfoUlE0Jd_uploads_git_blob_9864c7f811c613c3faab876659c6423__25[[#This Row],[Estado de la Mesa]]="Ocupada",(15/1440)+spaces_3iWczBNnn5rbfoUlE0Jd_uploads_git_blob_9864c7f811c613c3faab876659c6423__25[[#This Row],[Hora de salida2]]-spaces_3iWczBNnn5rbfoUlE0Jd_uploads_git_blob_9864c7f811c613c3faab876659c6423__25[[#This Row],[Hora de llegada2]],spaces_3iWczBNnn5rbfoUlE0Jd_uploads_git_blob_9864c7f811c613c3faab876659c6423__25[[#This Row],[Estado de la Mesa]]<>"Ocupada",spaces_3iWczBNnn5rbfoUlE0Jd_uploads_git_blob_9864c7f811c613c3faab876659c6423__25[[#This Row],[Hora de salida2]]-spaces_3iWczBNnn5rbfoUlE0Jd_uploads_git_blob_9864c7f811c613c3faab876659c6423__25[[#This Row],[Hora de llegada2]])} -> 0.078472222 | S17: =_xlfn.XLOOKUP(spaces_3iWczBNnn5rbfoUlE0Jd_uploads_git_blob_9864c7f811c613c3faab876659c6423__25[[#This Row],[Número de Orden]],Cocinadinamica!E18:E786,Cocinadinamica!F18:F786)/1440 -> 0.026388889 | T17: {=_xlfn.IFS((spaces_3iWczBNnn5rbfoUlE0Jd_uploads_git_blob_9864c7f811c613c3faab876659c6423__25[[#This Row],[Tiempo de permanencia]]-spaces_3iWczBNnn5rbfoUlE0Jd_uploads_git_blob_9864c7f811c613c3faab876659c6423__25[[#This Row],[Tiempo de preparación total]])>0,spaces_3iWczBNnn5rbfoUlE0Jd_uploads_git_blob_9864c7f811c613c3faab876659c6423__25[[#This Row],[Tiempo de permanencia]]-spaces_3iWczBNnn5rbfoUlE0Jd_uploads_git_blob_9864c7f811c613c3faab876659c6423__25[[#This Row],[Tiempo de preparación total]],spaces_3iWczBNnn5rbfoUlE0Jd_uploads_git_blob_9864c7f811c613c3faab876659c6423__25[[#This Row],[Tiempo de permanencia]]-spaces_3iWczBNnn5rbfoUlE0Jd_uploads_git_blob_9864c7f811c613c3faab876659c6423__25[[#This Row],[Tiempo de preparación total]]<0,0)} -> 0.052083333 | U17: {=_xlfn.IFS(spaces_3iWczBNnn5rbfoUlE0Jd_uploads_git_blob_9864c7f811c613c3faab876659c6423__25[[#This Row],[Tiempo degustación]]=0,"NO PAGADA",spaces_3iWczBNnn5rbfoUlE0Jd_uploads_git_blob_9864c7f811c613c3faab876659c6423__25[[#This Row],[Tiempo degustación]]>0, "PAGADA")} -> PAGADA
